<?xml version="1.0" ?>
<!-- =================================================================================== -->
<!-- |    This document was autogenerated by xacro from awtube31814v2.urdf.xacro       | -->
<!-- |    EDITING THIS FILE BY HAND IS NOT RECOMMENDED                                 | -->
<!-- =================================================================================== -->
<robot name="awtube31814v2">
  <link name="awtube_base_link">
    <inertial>
      <origin rpy="0 0 0" xyz="3.1408E-18 2.3265E-19 0.011306"/>
      <mass value="1.95"/>
      <inertia ixx="0.0069682" ixy="0" ixz="0" iyy="0.00698365" iyz="0" izz="0.013625"/>
    </inertial>
    <visual>
      <origin rpy="0 0 0" xyz="0 0 0"/>
      <geometry>
        <mesh filename="package://awtube31814v2/meshes/awtube3_baselink.STL"/>
      </geometry>
      <material name="">
        <color rgba="0.79216 0.81961 0.93333 1"/>
      </material>
    </visual>
    <collision>
      <origin rpy="0 0 0" xyz="0 0 0"/>
      <geometry>
        <mesh filename="package://awtube31814v2/meshes/controllo/awtube3_baselink.STL"/>
      </geometry>
    </collision>
  </link>
  <link name="awtube_link1">
    <inertial>
      <origin rpy="0 0 0" xyz="-4E-05 0.00349 0.07595"/>
      <mass value="16.68"/>
      <inertia ixx="0.094951" ixy="2.147E-05" ixz="-2.303E-05" iyy="0.092817" iyz="0.0081897" izz="0.070923"/>
    </inertial>
    <visual>
      <origin rpy="0 0 0" xyz="0 0 0"/>
      <geometry>
        <mesh filename="package://awtube31814v2/meshes/awtube3_link1.STL"/>
      </geometry>
      <material name="">
        <color rgba="0.79216 0.81961 0.93333 1"/>
      </material>
    </visual>
    <collision>
      <origin rpy="0 0 0" xyz="0 0 0"/>
      <geometry>
        <mesh filename="package://awtube31814v2/meshes/controllo/awtube3_link1.STL"/>
      </geometry>
    </collision>
  </link>
  <joint name="awtube_joint1" type="revolute">
    <origin rpy="0 0 0" xyz="0 0 0.025"/>
    <parent link="awtube_base_link"/>
    <child link="awtube_link1"/>
    <axis xyz="0 0 -1"/>
    <limit effort="600" lower="-3.14" upper="3.14" velocity="1.2436"/>
    <dynamics damping="1" friction="0.1"/>
  </joint>
  <link name="awtube_link2">
    <inertial>
      <origin rpy="0 0 0" xyz="3.3616E-13 0.34153 0.12"/>
      <mass value="40.32"/>
      <inertia ixx="4.5836" ixy="0.000709" ixz="0.000204" iyy="0.2329" iyz="0.14739" izz="4.5148"/>
    </inertial>
    <visual>
      <origin rpy="0 0 0" xyz="0 0 0"/>
      <geometry>
        <mesh filename="package://awtube31814v2/meshes/awtube3_link2.STL"/>
      </geometry>
      <material name="">
        <color rgba="0.79216 0.81961 0.93333 1"/>
      </material>
    </visual>
    <collision>
      <origin rpy="0 0 0" xyz="0 0 0"/>
      <geometry>
        <mesh filename="package://awtube31814v2/meshes/controllo/awtube3_link2.STL"/>
      </geometry>
    </collision>
  </link>
  <joint name="awtube_joint2" type="revolute">
    <origin rpy="1.5708 0 3.1416" xyz="0 0.1045 0.092"/>
    <parent link="awtube_link1"/>
    <child link="awtube_link2"/>
    <axis xyz="0 0 -1"/>
    <limit effort="690" lower="-3.14" upper="3.14" velocity="0.86"/>
    <dynamics damping="1" friction="0.1"/>
  </joint>
  <link name="awtube_link3">
    <inertial>
      <origin rpy="0 0 0" xyz="0.00175 -1.8E-05 0.12"/>
      <mass value="11.25"/>
      <inertia ixx="0.058476" ixy="0.0001111" ixz="-0.000703" iyy="0.075816" iyz="5.64E-05" izz="0.048525"/>
    </inertial>
    <visual>
      <origin rpy="0 0 0" xyz="0 0 0"/>
      <geometry>
        <mesh filename="package://awtube31814v2/meshes/awtube3_link3.STL"/>
      </geometry>
      <material name="">
        <color rgba="0.79216 0.81961 0.93333 1"/>
      </material>
    </visual>
    <collision>
      <origin rpy="0 0 0" xyz="0 0 0"/>
      <geometry>
        <mesh filename="package://awtube31814v2/meshes/controllo/awtube3_link3.STL"/>
      </geometry>
    </collision>
  </link>
  <joint name="awtube_joint3" type="revolute">
    <origin rpy="-3.1416 0 -3.1416" xyz="0 0.725 0.0495"/>
    <parent link="awtube_link2"/>
    <child link="awtube_link3"/>
    <axis xyz="0 0 -1"/>
    <limit effort="350" lower="-4.71" upper="1.57" velocity="1.24"/>
    <dynamics damping="1" friction="0.1"/>
  </joint>
  <link name="awtube_link4">
    <inertial>
      <origin rpy="0 0 0" xyz="0.00017 -0.0006 0.52"/>
      <mass value="10.24"/>
      <inertia ixx="0.26862" ixy="-0.00010157" ixz="0.0004927" iyy="0.25451" iyz="0.00037679" izz="0.038222"/>
    </inertial>
    <visual>
      <origin rpy="0 0 0" xyz="0 0 0"/>
      <geometry>
        <mesh filename="package://awtube31814v2/meshes/awtube3_link4.STL"/>
      </geometry>
      <material name="">
        <color rgba="0.79216 0.81961 0.93333 1"/>
      </material>
    </visual>
    <collision>
      <origin rpy="0 0 0" xyz="0 0 0"/>
      <geometry>
        <mesh filename="package://awtube31814v2/meshes/controllo/awtube3_link4.STL"/>
      </geometry>
    </collision>
  </link>
  <joint name="awtube_joint4" type="revolute">
    <origin rpy="-1.5708 0 -1.5708" xyz="0.0924 0 0.154"/>
    <parent link="awtube_link3"/>
    <child link="awtube_link4"/>
    <axis xyz="0 0 -1"/>
    <limit effort="145" lower="-8.0" upper="8.0" velocity="2.71"/>
    <dynamics damping="1" friction="0.1"/>
  </joint>
  <link name="awtube_link5">
    <inertial>
      <origin rpy="0 0 0" xyz="0.216 0.00011 -0.057"/>
      <mass value="5.53"/>
      <inertia ixx="0.021874" ixy="2.249E-05" ixz="-0.013555" iyy="0.051476" iyz="8.85E-06" izz="0.043133"/>
    </inertial>
    <visual>
      <origin rpy="0 0 0" xyz="0 0 0"/>
      <geometry>
        <mesh filename="package://awtube31814v2/meshes/awtube3_link5.STL"/>
      </geometry>
      <material name="">
        <color rgba="0.69804 0.69804 0.69804 1"/>
      </material>
    </visual>
    <collision>
      <origin rpy="0 0 0" xyz="0 0 0"/>
      <geometry>
        <mesh filename="package://awtube31814v2/meshes/controllo/awtube3_link5.STL"/>
      </geometry>
    </collision>
  </link>
  <joint name="awtube_joint5" type="revolute">
    <origin rpy="-1.5708 -1.5708 0" xyz="0 0.0924 0.5827"/>
    <parent link="awtube_link4"/>
    <child link="awtube_link5"/>
    <axis xyz="0 0 -1"/>
    <limit effort="145" lower="-1.6" upper="4.71" velocity="2.71"/>
    <dynamics damping="1" friction="0.1"/>
  </joint>
  <link name="awtube_link6">
    <inertial>
      <origin rpy="0 0 0" xyz="7E-05 8E-05 -0.02571"/>
      <mass value="0.41"/>
      <inertia ixx="0.00032966" ixy="-4.2E-07" ixz="-2.8E-07" iyy="0.00032977" iyz="5.4E-07" izz="0.00054114"/>
    </inertial>
    <visual>
      <origin rpy="0 0 0" xyz="0 0 0"/>
      <geometry>
        <mesh filename="package://awtube31814v2/meshes/awtube3_link6.STL"/>
      </geometry>
      <material name="">
        <color rgba="0.8902 0.8902 0.91373 1"/>
      </material>
    </visual>
    <collision>
      <origin rpy="0 0 0" xyz="0 0 0"/>
      <geometry>
        <mesh filename="package://awtube31814v2/meshes/controllo/awtube3_link6.STL"/>
      </geometry>
    </collision>
  </link>
  <joint name="awtube_joint6" type="revolute">
    <origin rpy="1.5708 0 3.1416" xyz="0 0.358 -0.0919"/>
    <parent link="awtube_link5"/>
    <child link="awtube_link6"/>
    <axis xyz="0 0 -1"/>
    <limit effort="85" lower="-8.0" upper="8.0" velocity="3.61"/>
    <dynamics damping="1" friction="0.1"/>
  </joint>
</robot>
