<?xml version="2.0" encoding="utf-8"?>
<robot xmlns:xacro="http://www.ros.org/wiki/xacro" name="awtube3">

  <xacro:macro name="awtube3" params="arm_id:='awtube' connected_to:='' *origin">

    <xacro:unless value="${not connected_to}">
      <joint name="world" type="fixed">
        <parent link="${connected_to}" />
        <child link="${arm_id}_base_link" />
        <xacro:insert_block name="origin" />
      </joint>
    </xacro:unless>
    <link
      name="${arm_id}_base_link">
      <inertial>
        <origin
          xyz="3.1408E-18 2.3265E-19 0.011306"
          rpy="0 0 0" />
        <mass
          value="1.95" />
        <inertia
          ixx="0.0069682"
          ixy="0"
          ixz="0"
          iyy="0.00698365"
          iyz="0"
          izz="0.013625" />
      </inertial>
      <visual>
        <origin
          xyz="0 0 0"
          rpy="0 0 0" />
        <geometry>
          <mesh
            filename="package://awtube31814v2/meshes/awtube3_baselink.STL" />
        </geometry>
        <material
          name="">
          <color
            rgba="0.79216 0.81961 0.93333 1" />
        </material>
      </visual>
      <collision>
        <origin
          xyz="0 0 0"
          rpy="0 0 0" />
        <geometry>
          <mesh
            filename="package://awtube31814v2/meshes/controllo/awtube3_baselink.STL" />
        </geometry>
      </collision>
    </link>
    <link
      name="${arm_id}_link1">
      <inertial>
        <origin
          xyz="-4E-05 0.00349 0.07595"
          rpy="0 0 0" />
        <mass
          value="16.68" />
        <inertia
          ixx="0.094951"
          ixy="2.147E-05"
          ixz="-2.303E-05"
          iyy="0.092817"
          iyz="0.0081897"
          izz="0.070923" />
      </inertial>
      <visual>
        <origin
          xyz="0 0 0"
          rpy="0 0 0" />
        <geometry>
          <mesh
            filename="package://awtube31814v2/meshes/awtube3_link1.STL" />
        </geometry>
        <material
          name="">
          <color
            rgba="0.79216 0.81961 0.93333 1" />
        </material>
      </visual>
      <collision>
        <origin
          xyz="0 0 0"
          rpy="0 0 0" />
        <geometry>
          <mesh
            filename="package://awtube31814v2/meshes/controllo/awtube3_link1.STL" />
        </geometry>
      </collision>
    </link>
    <joint
      name="${arm_id}_joint1"
      type="revolute">
      <origin
        xyz="0 0 0.025"
        rpy="0 0 0" />
      <parent
        link="${arm_id}_base_link" />
      <child
        link="${arm_id}_link1" />
      <axis
        xyz="0 0 -1" />
      <limit
        lower="-3.14"
        upper="3.14"
        effort="600"
        velocity="1.2436" />
      <dynamics
        damping="1"
        friction="0.1" />
    </joint>
    <link
      name="${arm_id}_link2">
      <inertial>
        <origin
          xyz="3.3616E-13 0.34153 0.12"
          rpy="0 0 0" />
        <mass
          value="40.32" />
        <inertia
          ixx="4.5836"
          ixy="0.000709"
          ixz="0.000204"
          iyy="0.2329"
          iyz="0.14739"
          izz="4.5148" />
      </inertial>
      <visual>
        <origin
          xyz="0 0 0"
          rpy="0 0 0" />
        <geometry>
          <mesh
            filename="package://awtube31814v2/meshes/awtube3_link2.STL" />
        </geometry>
        <material
          name="">
          <color
            rgba="0.79216 0.81961 0.93333 1" />
        </material>
      </visual>
      <collision>
        <origin
          xyz="0 0 0"
          rpy="0 0 0" />
        <geometry>
          <mesh
            filename="package://awtube31814v2/meshes/controllo/awtube3_link2.STL" />
        </geometry>
      </collision>
    </link>
    <joint
      name="${arm_id}_joint2"
      type="revolute">
      <origin
        xyz="0 0.1045 0.092"
        rpy="1.5708 0 3.1416" />
      <parent
        link="${arm_id}_link1" />
      <child
        link="${arm_id}_link2" />
      <axis
        xyz="0 0 -1" />
      <limit
        lower="-3.14"
        upper="3.14"
        effort="690"
        velocity="0.86" />
      <dynamics
        damping="1"
        friction="0.1" />
    </joint>
    <link
      name="${arm_id}_link3">
      <inertial>
        <origin
          xyz="0.00175 -1.8E-05 0.12"
          rpy="0 0 0" />
        <mass
          value="11.25" />
        <inertia
          ixx="0.058476"
          ixy="0.0001111"
          ixz="-0.000703"
          iyy="0.075816"
          iyz="5.64E-05"
          izz="0.048525" />
      </inertial>
      <visual>
        <origin
          xyz="0 0 0"
          rpy="0 0 0" />
        <geometry>
          <mesh
            filename="package://awtube31814v2/meshes/awtube3_link3.STL" />
        </geometry>
        <material
          name="">
          <color
            rgba="0.79216 0.81961 0.93333 1" />
        </material>
      </visual>
      <collision>
        <origin
          xyz="0 0 0"
          rpy="0 0 0" />
        <geometry>
          <mesh
            filename="package://awtube31814v2/meshes/controllo/awtube3_link3.STL" />
        </geometry>
      </collision>
    </link>
    <joint
      name="${arm_id}_joint3"
      type="revolute">
      <origin
        xyz="0 0.725 0.0495"
        rpy="-3.1416 0 -3.1416" />
      <parent
        link="${arm_id}_link2" />
      <child
        link="${arm_id}_link3" />
      <axis
        xyz="0 0 1" />
      <limit
        lower="-4.71"
        upper="4.71"
        effort="350"
        velocity="1.24" />
      <dynamics
        damping="1"
        friction="0.1" />
    </joint>
    <link
      name="${arm_id}_link4">
      <inertial>
        <origin
          xyz="0.00017 -0.0006 0.52"
          rpy="0 0 0" />
        <mass
          value="10.24" />
        <inertia
          ixx="0.26862"
          ixy="-0.00010157"
          ixz="0.0004927"
          iyy="0.25451"
          iyz="0.00037679"
          izz="0.038222" />
      </inertial>
      <visual>
        <origin
          xyz="0 0 0"
          rpy="0 0 0" />
        <geometry>
          <mesh
            filename="package://awtube31814v2/meshes/awtube3_link4.STL" />
        </geometry>
        <material
          name="">
          <color
            rgba="0.79216 0.81961 0.93333 1" />
        </material>
      </visual>
      <collision>
        <origin
          xyz="0 0 0"
          rpy="0 0 0" />
        <geometry>
          <mesh
            filename="package://awtube31814v2/meshes/controllo/awtube3_link4.STL" />
        </geometry>
      </collision>
    </link>
    <joint
      name="${arm_id}_joint4"
      type="revolute">
      <origin
        xyz="0.0924 0 0.154"
        rpy="-1.5708 0 -1.5708" />
      <parent
        link="${arm_id}_link3" />
      <child
        link="${arm_id}_link4" />
      <axis
        xyz="0 0 -1" />
      <limit
        lower="-8.0"
        upper="8.0"
        effort="145"
        velocity="2.71" />
      <dynamics
        damping="1"
        friction="0.1" />
    </joint>
    <link
      name="${arm_id}_link5">
      <inertial>
        <origin
          xyz="0.216 0.00011 -0.057"
          rpy="0 0 0" />
        <mass
          value="5.53" />
        <inertia
          ixx="0.021874"
          ixy="2.249E-05"
          ixz="-0.013555"
          iyy="0.051476"
          iyz="8.85E-06"
          izz="0.043133" />
      </inertial>
      <visual>
        <origin
          xyz="0 0 0"
          rpy="0 0 0" />
        <geometry>
          <mesh
            filename="package://awtube31814v2/meshes/awtube3_link5.STL" />
        </geometry>
        <material
          name="">
          <color
            rgba="0.69804 0.69804 0.69804 1" />
        </material>
      </visual>
      <collision>
        <origin
          xyz="0 0 0"
          rpy="0 0 0" />
        <geometry>
          <mesh
            filename="package://awtube31814v2/meshes/controllo/awtube3_link5.STL" />
        </geometry>
      </collision>
    </link>
    <joint
      name="${arm_id}_joint5"
      type="revolute">
      <origin
        xyz="0 0.0924 0.5827"
        rpy="-1.5708 -1.5708 0" />
      <parent
        link="${arm_id}_link4" />
      <child
        link="${arm_id}_link5" />
      <axis
        xyz="0 0 -1" />
      <limit
        lower="-4.71"
        upper="4.71"
        effort="145"
        velocity="2.71" />
      <dynamics
        damping="1"
        friction="0.1" />
    </joint>
    <link
      name="${arm_id}_link6">
      <inertial>
        <origin
          xyz="7E-05 8E-05 -0.02571"
          rpy="0 0 0" />
        <mass
          value="0.41" />
        <inertia
          ixx="0.00032966"
          ixy="-4.2E-07"
          ixz="-2.8E-07"
          iyy="0.00032977"
          iyz="5.4E-07"
          izz="0.00054114" />
      </inertial>
      <visual>
        <origin
          xyz="0 0 0"
          rpy="0 0 0" />
        <geometry>
          <mesh
            filename="package://awtube31814v2/meshes/awtube3_link6.STL" />
        </geometry>
        <material
          name="">
          <color
            rgba="0.8902 0.8902 0.91373 1" />
        </material>
      </visual>
      <collision>
        <origin
          xyz="0 0 0"
          rpy="0 0 0" />
        <geometry>
          <mesh
            filename="package://awtube31814v2/meshes/controllo/awtube3_link6.STL" />
        </geometry>
      </collision>
    </link>
    <joint
      name="${arm_id}_joint6"
      type="revolute">
      <origin
        xyz="0 0.358 -0.0919"
        rpy="1.5708 0 3.1416" />
      <parent
        link="${arm_id}_link5" />
      <child
        link="${arm_id}_link6" />
      <axis
        xyz="0 0 -1" />
      <limit
        lower="-8.0"
        upper="8.0"
        effort="85"
        velocity="3.61" />
      <dynamics
        damping="1"
        friction="0.1" />
    </joint>
  </xacro:macro>

</robot>